Workbook

Sheet About_This_Data
A1: Field | B1: Value
A2: Company | B2: Lumina Living Pte Ltd - fictional Singapore home-living retailer; HR Shared Services case data
A3: Reporting date | B3: 46295
A4: Scope | B4: 120 Q3 2026 HR cases, five departments. All identities and records are synthetic.
A5: Meaning | B5: Cost_SGD is the recorded HR case handling cost of all statuses; not a budget or productivity claim.
A6: Rejoin | B6: This input is a deterministic checkpoint, not proof of your Copilot output.

Sheet HR_Cases
A1: Case_ID | B1: Department | C1: Request_Type | D1: Priority | E1: Status | F1: Assigned_To | G1: Opened_Date | H1: Due_Date | I1: Closed_Date | J1: Estimated_Hours | K1: Actual_Hours | L1: Cost_SGD | M1: Description
A2: HR-2026-0001 | B2: Retail Sales | C2: Leave Request | D2: Low | E2: Closed | F2: Aisha Tan | G2: 46290 | H2: 46297 | I2: 46295 | J2: 2 | K2: 1 | L2: 90 | M2: Leave Request employee case 001
A3: HR-2026-0002 | B3: Retail Sales | C3: Leave Request | D3: Medium | E3: Closed | F3: Ben Lim | G3: 46289 | H3: 46297 | I3: 46295 | J3: 3 | K3: 2 | L3: 125.5 | M3: Leave Request employee case 002
A4: HR-2026-0003 | B4: Retail Sales | C4: Leave Request | D4: High | E4: In Progress | F4: Chloe Goh | G4: 46288 | H4: 46297 | J4: 4 | K4: 0 | L4: 161 | M4: Leave Request employee case 003
A5: HR-2026-0004 | B5: Operations | C5: Leave Request | D5: Critical | E5: On Hold | F5: Daniel Lee | G5: 46287 | H5: 46297 | J5: 5 | K5: 0 | L5: 196.5 | M5: Leave Request employee case 004
A6: HR-2026-0005 | B6: Operations | C6: Training Request | D6: Low | E6: New | F6: Elena Ong | G6: 46286 | H6: 46297 | J6: 6 | K6: 0 | L6: 232 | M6: Training Request employee case 005
A7: HR-2026-0006 | B7: Operations | C7: Training Request | D7: Medium | E7: Closed | F7: Farid Rahman | G7: 46285 | H7: 46297 | I7: 46295 | J7: 7 | K7: 6 | L7: 267.5 | M7: Training Request employee case 006
A8: HR-2026-0007 | B8: Finance | C8: Training Request | D8: High | E8: Closed | F8: Grace Ng | G8: 46284 | H8: 46297 | I8: 46295 | J8: 8 | K8: 7 | L8: 303 | M8: Training Request employee case 007
A9: HR-2026-0008 | B9: Finance | C9: Training Request | D9: Critical | E9: On Hold | F9: Hari Kumar | G9: 46283 | H9: 46297 | J9: 2 | K9: 0 | L9: 338.5 | M9: Training Request employee case 008
A10: HR-2026-0009 | B10: Finance | C10: Onboarding | D10: Low | E10: New | F10: Aisha Tan | G10: 46282 | H10: 46297 | J10: 3 | K10: 0 | L10: 374 | M10: Onboarding employee case 009
A11: HR-2026-0010 | B11: Marketing | C11: Onboarding | D11: Medium | E11: Cancelled | F11: Ben Lim | G11: 46281 | H11: 46297 | J11: 4 | K11: 0 | L11: 409.5 | M11: Onboarding employee case 010
A12: HR-2026-0011 | B12: Marketing | C12: Onboarding | D12: High | E12: Closed | F12: Chloe Goh | G12: 46280 | H12: 46287 | I12: 46287 | J12: 5 | K12: 2 | L12: 445 | M12: Onboarding employee case 011
A13: HR-2026-0012 | B13: Marketing | C13: Onboarding | D13: Critical | E13: Closed | F13: Daniel Lee | G13: 46279 | H13: 46287 | I13: 46287 | J13: 6 | K13: 3 | L13: 480.5 | M13: Onboarding employee case 012
A14: HR-2026-0013 | B14: Technology | C14: Payroll Query | D14: Low | E14: New | G14: 46278 | H14: 46287 | J14: 7 | K14: 0 | L14: 516 | M14: Payroll Query employee case 013
A15: HR-2026-0014 | B15: Technology | C15: Payroll Query | D15: Medium | E15: Assigned | F15: Farid Rahman | G15: 46277 | H15: 46287 | J15: 8 | K15: 0 | L15: 90 | M15: Payroll Query employee case 014
A16: HR-2026-0015 | B16: Technology | C16: Payroll Query | D16: High | E16: In Progress | F16: Grace Ng | G16: 46276 | H16: 46287 | J16: 2 | K16: 0 | L16: 125.5 | M16: Payroll Query employee case 015
A17: HR-2026-0016 | B17: Retail Sales | C17: Payroll Query | D17: Critical | E17: Closed | F17: Hari Kumar | G17: 46275 | H17: 46287 | I17: 46288 | J17: 3 | K17: 7 | L17: 161 | M17: Payroll Query employee case 016
A18: HR-2026-0017 | B18: Retail Sales | C18: Benefits Claim | D18: Low | E18: Closed | F18: Aisha Tan | G18: 46274 | H18: 46287 | I18: 46288 | J18: 4 | K18: 8 | L18: 196.5 | M18: Benefits Claim employee case 017
A19: HR-2026-0018 | B19: Retail Sales | C19: Benefits Claim | D19: Medium | E19: Assigned | F19: Ben Lim | G19: 46273 | H19: 46287 | J19: 5 | K19: 0 | L19: 232 | M19: Benefits Claim employee case 018
A20: HR-2026-0019 | B20: Operations | C20: Benefits Claim | D20: High | E20: In Progress | F20: Chloe Goh | G20: 46272 | H20: 46287 | J20: 6 | K20: 0 | L20: 267.5 | M20: Benefits Claim employee case 019
A21: HR-2026-0020 | B21: Operations | C21: Benefits Claim | D21: Critical | E21: Cancelled | F21: Daniel Lee | G21: 46271 | H21: 46287 | J21: 7 | K21: 0 | L21: 303 | M21: Benefits Claim employee case 020
A22: HR-2026-0021 | B22: Operations | C22: Leave Request | D22: Low | E22: Closed | F22: Elena Ong | G22: 46270 | H22: 46277 | I22: 46279 | J22: 8 | K22: 3 | L22: 338.5 | M22: Leave Request employee case 021
A23: HR-2026-0022 | B23: Finance | C23: Leave Request | D23: Medium | E23: Closed | F23: Farid Rahman | G23: 46269 | H23: 46277 | I23: 46279 | J23: 2 | K23: 4 | L23: 374 | M23: Leave Request employee case 022
A24: HR-2026-0023 | B24: Finance | C24: Leave Request | D24: High | E24: In Progress | F24: Grace Ng | G24: 46268 | H24: 46277 | J24: 3 | K24: 0 | L24: 409.5 | M24: Leave Request employee case 023
A25: HR-2026-0024 | B25: Finance | C25: Leave Request | D25: Critical | E25: On Hold | F25: Hari Kumar | G25: 46267 | H25: 46277 | J25: 4 | K25: 0 | L25: 445 | M25: Leave Request employee case 024
A26: HR-2026-0025 | B26: Marketing | C26: Training Request | D26: Low | E26: New | G26: 46266 | H26: 46277 | J26: 5 | K26: 0 | L26: 480.5 | M26: Training Request employee case 025
A27: HR-2026-0026 | B27: Marketing | C27: Training Request | D27: Medium | E27: Closed | F27: Ben Lim | G27: 46265 | H27: 46277 | I27: 46275 | J27: 6 | K27: 8 | L27: 516 | M27: Training Request employee case 026
A28: HR-2026-0027 | B28: Marketing | C28: Training Request | D28: High | E28: Closed | F28: Chloe Goh | G28: 46264 | H28: 46277 | I28: 46275 | J28: 7 | K28: 9 | L28: 90 | M28: Training Request employee case 027
A29: HR-2026-0028 | B29: Technology | C29: Training Request | D29: Critical | E29: On Hold | F29: Daniel Lee | G29: 46263 | H29: 46277 | J29: 8 | K29: 0 | L29: 125.5 | M29: Training Request employee case 028
A30: HR-2026-0029 | B30: Technology | C30: Onboarding | D30: Low | E30: New | F30: Elena Ong | G30: 46262 | H30: 46277 | J30: 2 | K30: 0 | L30: 161 | M30: Onboarding employee case 029
A31: HR-2026-0030 | B31: Technology | C31: Onboarding | D31: Medium | E31: Cancelled | F31: Farid Rahman | G31: 46261 | H31: 46277 | J31: 3 | K31: 0 | L31: 196.5 | M31: Onboarding employee case 030
A32: HR-2026-0031 | B32: Retail Sales | C32: Onboarding | D32: High | E32: Closed | F32: Grace Ng | G32: 46260 | H32: 46267 | I32: 46266 | J32: 4 | K32: 4 | L32: 232 | M32: Onboarding employee case 031
A33: HR-2026-0032 | B33: Retail Sales | C33: Onboarding | D33: Critical | E33: Closed | F33: Hari Kumar | G33: 46259 | H33: 46267 | I33: 46266 | J33: 5 | K33: 5 | L33: 267.5 | M33: Onboarding employee case 032
A34: HR-2026-0033 | B34: Retail Sales | C34: Payroll Query | D34: Low | E34: New | F34: Aisha Tan | G34: 46258 | H34: 46267 | J34: 6 | K34: 0 | L34: 303 | M34: Payroll Query employee case 033
A35: HR-2026-0034 | B35: Operations | C35: Payroll Query | D35: Medium | E35: Assigned | F35: Ben Lim | G35: 46257 | H35: 46267 | J35: 7 | K35: 0 | L35: 338.5 | M35: Payroll Query employee case 034
A36: HR-2026-0035 | B36: Operations | C36: Payroll Query | D36: High | E36: In Progress | F36: Chloe Goh | G36: 46256 | H36: 46267 | J36: 8 | K36: 0 | L36: 374 | M36: Payroll Query employee case 035
A37: HR-2026-0036 | B37: Operations | C37: Payroll Query | D37: Critical | E37: Closed | F37: Daniel Lee | G37: 46255 | H37: 46267 | I37: 46267 | J37: 2 | K37: 9 | L37: 409.5 | M37: Payroll Query employee case 036
A38: HR-2026-0037 | B38: Finance | C38: Benefits Claim | D38: Low | E38: Closed | F38: Elena Ong | G38: 46254 | H38: 46267 | I38: 46267 | J38: 3 | K38: 1 | L38: 445 | M38: Benefits Claim employee case 037
A39: HR-2026-0038 | B39: Finance | C39: Benefits Claim | D39: Medium | E39: Assigned | F39: Farid Rahman | G39: 46253 | H39: 46267 | J39: 4 | K39: 0 | L39: 480.5 | M39: Benefits Claim employee case 038
A40: HR-2026-0039 | B40: Finance | C40: Benefits Claim | D40: High | E40: In Progress | F40: Grace Ng | G40: 46252 | H40: 46267 | J40: 5 | K40: 0 | L40: 516 | M40: Benefits Claim employee case 039
...

Sheet HR_Officers
A1: HR_Officer | B1: Primary_Category | C1: Available_Hours_Week | D1: Home_Department
A2: Aisha Tan | B2: Leave Request | C2: 35 | D2: Retail Sales
A3: Ben Lim | B3: Leave Request | C3: 30 | D3: Operations
A4: Chloe Goh | B4: Leave Request | C4: 35 | D4: Finance
A5: Daniel Lee | B5: Leave Request | C5: 30 | D5: Marketing
A6: Elena Ong | B6: Training Request | C6: 35 | D6: Technology
A7: Farid Rahman | B7: Training Request | C7: 30 | D7: Retail Sales
A8: Grace Ng | B8: Training Request | C8: 35 | D8: Operations
A9: Hari Kumar | B9: Training Request | C9: 30 | D9: Finance

Sheet Control
A1: Metric | B1: Expected / control
A2: Report_Date | B2: 46295
A3: total | B3: 120
A4: closed | B4: 48
A5: cancelled | B5: 12
A6: backlog | B6: 60
A7: overdue | B7: 50
A8: unassigned_backlog | B8: 6
A9: on_time_closed | B9: 30
A10: on_time_rate | B10: 0.625
A11: cost | B11: 35827.5
A12: Backlog definition | B12: Status is neither Closed nor Cancelled
A13: Overdue definition | B13: Backlog and Due_Date strictly earlier than Report_Date
A14: On-time definition | B14: Closed_Date <= Due_Date; denominator Closed only
A15: Unknown assignment | B15: Blank Assigned_To stays blank; propose separately

Sheet Prompt_Log
A1: Step | B1: App / mode | C1: Prompt | D1: What Copilot did | E1: How I verified | F1: Decision

Sheet Checks
A1: Check | B1: Formula / evidence | C1: Result
A2: Total clean rows | B2: =ROWS(tblHRCases[Case_ID])

Sheet .Rules
A1: ## SOURCE AND SCOPE
A2: Preserve HR_Cases, tblHRCases, HR_Officers, current Assigned_To values and source IDs.
A3: Use the reporting date from Control!B2. State the selected Department, Request_Type, Status and Assigned_To scope beside every report.
A4: Backlog excludes Closed and Cancelled. Overdue backlog has Due_Date strictly before Control!B2.
A5: On-time closure rate uses Closed rows only, with Closed_Date <= Due_Date. Display N/A when no Closed rows remain.
A6: ## FORMATS AND VISUALS
A7: Display recorded Cost_SGD as S$ with two decimals; keep underlying values exact. Show dates as DD-MMM-YYYY.
A8: Use white backgrounds, navy titles, blue and teal accents, readable labels and named units; never use colour alone.
A9: ## OUTPUT AND REVIEW
A10: Use structured table references. Preserve the visible .Rules sheet and unrelated sheets, charts and Prompt_Log.
A11: Keep current owners separate from unapproved assignment proposals. Missing facts and approvals remain UNKNOWN.
A12: Ask before replacing named output sheets. Reconcile every count, rate and chart against source rows; do not duplicate outputs on rerun.
A13: ="Reporting date: "&TEXT(Control!B2,"yyyy-mm-dd")

Sheet Pareto_Request_Type
A1: Request_Type | B1: Count | C1: Cumulative_Count | D1: Share | E1: Cumulative_Percent
A2: Payroll Query | B2: =COUNTIFS(tblHRCases[Request_Type],A2,tblHRCases[Status],"<>Closed",tblHRCases[Status],"<>Cancelled",tblHRCases[Due_Date],"<"&Control!$B$2) | C2: =SUM($B$2:B2) | D2: =IF(SUM($B$2:$B$6)=0,"N/A",B2/SUM($B$2:$B$6)) | E2: =IF(SUM($B$2:$B$6)=0,"N/A",C2/SUM($B$2:$B$6))
A3: Benefits Claim | B3: =COUNTIFS(tblHRCases[Request_Type],A3,tblHRCases[Status],"<>Closed",tblHRCases[Status],"<>Cancelled",tblHRCases[Due_Date],"<"&Control!$B$2) | C3: =SUM($B$2:B3) | D3: =IF(SUM($B$2:$B$6)=0,"N/A",B3/SUM($B$2:$B$6)) | E3: =IF(SUM($B$2:$B$6)=0,"N/A",C3/SUM($B$2:$B$6))
A4: Leave Request | B4: =COUNTIFS(tblHRCases[Request_Type],A4,tblHRCases[Status],"<>Closed",tblHRCases[Status],"<>Cancelled",tblHRCases[Due_Date],"<"&Control!$B$2) | C4: =SUM($B$2:B4) | D4: =IF(SUM($B$2:$B$6)=0,"N/A",B4/SUM($B$2:$B$6)) | E4: =IF(SUM($B$2:$B$6)=0,"N/A",C4/SUM($B$2:$B$6))
A5: Training Request | B5: =COUNTIFS(tblHRCases[Request_Type],A5,tblHRCases[Status],"<>Closed",tblHRCases[Status],"<>Cancelled",tblHRCases[Due_Date],"<"&Control!$B$2) | C5: =SUM($B$2:B5) | D5: =IF(SUM($B$2:$B$6)=0,"N/A",B5/SUM($B$2:$B$6)) | E5: =IF(SUM($B$2:$B$6)=0,"N/A",C5/SUM($B$2:$B$6))
A6: Onboarding | B6: =COUNTIFS(tblHRCases[Request_Type],A6,tblHRCases[Status],"<>Closed",tblHRCases[Status],"<>Cancelled",tblHRCases[Due_Date],"<"&Control!$B$2) | C6: =SUM($B$2:B6) | D6: =IF(SUM($B$2:$B$6)=0,"N/A",B6/SUM($B$2:$B$6)) | E6: =IF(SUM($B$2:$B$6)=0,"N/A",C6/SUM($B$2:$B$6))
A8: Reporting date | B8: =Control!B2
A9: Scope | B9: All; overdue backlog only
A10: Interpretation | B10: Four categories first reach80%; counts show contribution, not cause.
